мы получим результат
1. Got the Test Exception
   Inside finally block